<?xml version="1.0" ?>
<!-- =================================================================================== -->
<!-- |    This document was autogenerated by xacro from airbot4.xacro                  | -->
<!-- |    EDITING THIS FILE BY HAND IS NOT RECOMMENDED                                 | -->
<!-- =================================================================================== -->
<robot name="Airbot" xmlns:xacro="http://www.ros.org/wiki/xacro">
  <!--Structural Properties-->
  <link name="baselink"/>
  <link name="airbase">
    <visual>
      <origin rpy="0 0 0" xyz="0.0 0.0 0.05"/>
      <geometry>
        <mesh filename="package://gcop_urdf/meshes/pelican1.dae" scale="0.025 0.025 0.025"/>
        <!--box size="0.3 ${l1} 0.5"/-->
      </geometry>
      <material name="blue">
        <color rgba="0 0 0.8 1"/>
      </material>
    </visual>
    <inertial>
      <mass value="3"/>
      <inertia ixx="0.01296" ixy="0.0" ixz="0.0" iyy="0.01296" iyz="0.0" izz="0.02523"/>
    </inertial>
  </link>
  <link name="link1">
    <visual>
      <origin rpy="0 0 0" xyz="0.0 0.05 0.0"/>
      <material name="blue">
        <color rgba="0 0 0.8 1"/>
      </material>
      <geometry>
        <box size="0.02 0.1 0.02"/>
      </geometry>
    </visual>
    <inertial>
      <origin rpy="0 0 0" xyz="0.0 0.05 0.0"/>
      <mass value="0.1"/>
      <inertia ixx="0.000346666666667" ixy="0.0" ixz="0.0" iyy="2.66666666667e-05" iyz="0.0" izz="0.000346666666667"/>
    </inertial>
  </link>
  <link name="link2">
    <visual>
      <origin rpy="0 0 0" xyz="0.0 0.0 -0.15"/>
      <geometry>
        <box size="0.02 0.02 0.3"/>
      </geometry>
      <material name="blue">
        <color rgba="0 0 0.8 1"/>
      </material>
    </visual>
    <inertial>
      <origin rpy="0 0 0" xyz="0.0 0.0 -0.15"/>
      <mass value="0.15"/>
      <inertia ixx="0.00452" ixy="0.0" ixz="0.0" iyy="0.00452" iyz="0.0" izz="4e-05"/>
    </inertial>
  </link>
  <link name="link3">
    <visual>
      <origin rpy="0 0 0" xyz="0.0 0.0 -0.15"/>
      <geometry>
        <box size="0.02 0.02 0.3"/>
      </geometry>
      <material name="blue">
        <color rgba="0 0 0.8 1"/>
      </material>
    </visual>
    <inertial>
      <origin rpy="0 0 0" xyz="0.0 0.0 -0.15"/>
      <mass value="0.1"/>
      <inertia ixx="0.00301333333333" ixy="0.0" ixz="0.0" iyy="0.00301333333333" iyz="0.0" izz="2.66666666667e-05"/>
    </inertial>
  </link>
  <link name="link4">
    <visual>
      <origin rpy="0 0 0" xyz="0.0 -0.05 0.0"/>
      <material name="red">
        <color rgba="0.8 0 0 1"/>
      </material>
      <geometry>
        <box size="0.02 0.1 0.02"/>
      </geometry>
    </visual>
    <inertial>
      <origin rpy="0 0 0" xyz="0.0 -0.05 0.0"/>
      <mass value="0.1"/>
      <inertia ixx="0.000346666666667" ixy="0.0" ixz="0.0" iyy="2.66666666667e-05" iyz="0.0" izz="0.000346666666667"/>
    </inertial>
  </link>
  <link name="link5">
    <visual>
      <origin rpy="0 0 0" xyz="0.0 0.0 -0.15"/>
      <geometry>
        <box size="0.02 0.02 0.3"/>
      </geometry>
      <material name="red">
        <color rgba="0.8 0 0 1"/>
      </material>
    </visual>
    <inertial>
      <origin rpy="0 0 0" xyz="0.0 0.0 -0.15"/>
      <mass value="0.15"/>
      <inertia ixx="0.00452" ixy="0.0" ixz="0.0" iyy="0.00452" iyz="0.0" izz="4e-05"/>
    </inertial>
  </link>
  <link name="link6">
    <visual>
      <origin rpy="0 0 0" xyz="0.0 0.0 -0.15"/>
      <geometry>
        <box size="0.02 0.02 0.3"/>
      </geometry>
      <material name="red">
        <color rgba="0.8 0 0 1"/>
      </material>
    </visual>
    <inertial>
      <origin rpy="0 0 0" xyz="0.0 0.0 -0.15"/>
      <mass value="0.1"/>
      <inertia ixx="0.00301333333333" ixy="0.0" ixz="0.0" iyy="0.00301333333333" iyz="0.0" izz="2.66666666667e-05"/>
    </inertial>
  </link>
  <!-- Joints -->
  <joint name="basetoairbase" type="fixed">
    <parent link="baselink"/>
    <child link="airbase"/>
    <origin rpy="0 0 0" xyz="0 0 0"/>
  </joint>
  <joint name="airbasetolink1" type="revolute">
    <parent link="airbase"/>
    <child link="link1"/>
    <origin rpy="0 0 0" xyz="0 0.1 -0.1"/>
    <axis xyz="0 0 1"/>
    <limit effort="30" lower="-3.14" upper="3.14" velocity="10.0"/>
  </joint>
  <joint name="link1tolink2" type="revolute">
    <parent link="link1"/>
    <child link="link2"/>
    <origin rpy="0 0 0" xyz="0 0.1 0"/>
    <axis xyz="0 1 0"/>
    <limit effort="30" lower="-3.14" upper="3.14" velocity="10.0"/>
  </joint>
  <joint name="link2tolink3" type="revolute">
    <parent link="link2"/>
    <child link="link3"/>
    <origin rpy="0 0 0" xyz="0 0 -0.3"/>
    <axis xyz="0 1 0"/>
    <limit effort="30" lower="-3.14" upper="3.14" velocity="10.0"/>
  </joint>
  <joint name="airbasetolink4" type="revolute">
    <parent link="airbase"/>
    <child link="link4"/>
    <origin rpy="0 0 0" xyz="0 -0.1 -0.1"/>
    <axis xyz="0 0 1"/>
    <limit effort="30" lower="-3.14" upper="3.14" velocity="10.0"/>
  </joint>
  <joint name="link4tolink5" type="revolute">
    <parent link="link4"/>
    <child link="link5"/>
    <origin rpy="0 0 0" xyz="0 -0.1 0"/>
    <axis xyz="0 1 0"/>
    <limit effort="30" lower="-3.14" upper="3.14" velocity="10.0"/>
  </joint>
  <joint name="link5tolink6" type="revolute">
    <parent link="link5"/>
    <child link="link6"/>
    <origin rpy="0 0 0" xyz="0 0 -0.3"/>
    <axis xyz="0 1 0"/>
    <limit effort="30" lower="-3.14" upper="3.14" velocity="10.0"/>
  </joint>
</robot>

