<?xml version="1.0"?>
<robot xmlns:xacro="http://www.ros.org/wiki/xacro" name="Chain">

<xacro:property name="m" value="1" />
<xacro:macro name="compute_inertia" params="mass x y z">
      <mass value="${mass}"/>
      <inertia ixx="${mass*(y*y + z*z)/3}" ixy="0.0" ixz="0.0" iyy="${mass*(x*x + z*z)/3}" iyz="0.0" izz="${mass*(x*x + y*y)/3}"/>
</xacro:macro>


  <link name="baselink"/>
  <link name="chainbase">
    <visual>
      <geometry>
        <box size="0.3 0.1 0.1"/>
      </geometry>
    </visual>
    <inertial>
			<xacro:compute_inertia mass="${m}" x="0.3" y="0.1" z="0.1"/>
    </inertial>
  </link>
  <link name="fixedlink">
    <visual>
      <geometry>
        <box size="0.1 0.1 0.1"/>
      </geometry>
    </visual>
    <inertial>
			<xacro:compute_inertia mass="${m}" x="0.1" y="0.1" z="0.1"/>
    </inertial>
  </link>
  <link name="link1">
    <visual>
			<origin rpy="0 0 0" xyz="0.05 0.0 0"/>
      <geometry>
        <box size="0.1 .10 0.05"/>
      </geometry>
      <material name="blue">
        <color rgba="0 0 0.8 1"/>
      </material>
    </visual>
    <inertial>
			<origin rpy="0 0 0" xyz="0.05 0.0 0"/>
			<xacro:compute_inertia mass="${m}" x="0.1" y="0.1" z="0.05"/>
    </inertial>
  </link>
  <link name="link2">
    <visual>
			<origin rpy="0 0 0" xyz="-0.05 0.0 0"/>
      <geometry>
        <box size="0.1 .10 0.05"/>
      </geometry>
      <material name="blue">
        <color rgba="0 0 0.8 1"/>
      </material>
    </visual>
    <inertial>
			<origin rpy="0 0 0" xyz="-0.05 0.0 0"/>
			<xacro:compute_inertia mass="${m}" x="0.1" y="0.1" z="0.05"/>
    </inertial>
  </link>
	<link name="link3">
    <visual>
			<origin rpy="0 0 0" xyz="0.0 0.0 0.05"/>
      <geometry>
        <box size="0.1 0.05 0.1"/>
      </geometry>
      <material name="red">
        <color rgba="0.8 0 0 1"/>
      </material>
    </visual>
    <inertial>
			<origin rpy="0 0 0" xyz="0.0 0.0 0.05"/>
			<xacro:compute_inertia mass="${m}" x="0.1" y="0.05" z="0.1"/>
    </inertial>
  </link>
	<link name="link4">
    <visual>
			<origin rpy="0 0 0" xyz="0.0 0.0 0.05"/>
      <geometry>
        <box size="0.1 0.05 0.1"/>
      </geometry>
      <material name="blue">
        <color rgba="0 0 0.8 1"/>
      </material>
    </visual>
    <inertial>
			<origin rpy="0 0 0" xyz="0.0 0.0 0.05"/>
			<xacro:compute_inertia mass="${m}" x="0.1" y="0.05" z="0.1"/>
    </inertial>
  </link>

 <!-- Joints -->
  <joint name="basetoroot" type="fixed">
    <parent link="baselink"/>
    <child link="chainbase"/>
    <origin rpy="0 0 0" xyz="0 0 0"/>
  </joint>
  <joint name="roottofixedlink1" type="fixed">
    <parent link="chainbase"/>
    <child link="fixedlink"/>
    <origin rpy="0 0 0" xyz="0.0 0.0 0.1"/>
  </joint>
	<joint name="fixedlinktolink3" type="fixed">
    <parent link="fixedlink"/>
    <child link="link3"/>
    <origin rpy="0 0 0" xyz="0.0 0.0 0.05"/>
  </joint>
	<joint name="link3tolink4" type="revolute">
    <parent link="link3"/>
    <child link="link4"/>
    <origin rpy="0 0 0" xyz="0.0 0.0 0.05"/>
    <axis xyz="0 -1 0"/>
		<limit effort="30" velocity="5.0" lower="-5" upper="5" />
  </joint>
  <joint name="roottolink1" type="revolute">
    <parent link="chainbase"/>
    <child link="link1"/>
    <origin rpy="0 0 0" xyz="0.15 0.0 0"/>
    <axis xyz="0 -1 0"/>
		<limit effort="30" velocity="5.0" lower="-5" upper="5" />
  </joint>
  <joint name="roottolink2" type="revolute">
    <parent link="chainbase"/>
    <child link="link2"/>
    <origin rpy="0 0 0" xyz="-0.15 0.0 0"/>
    <axis xyz="0 -1 0"/>
		<limit effort="30" velocity="5.0" lower="-5" upper="5" />
  </joint>
</robot>
