<?xml version="1.0" ?>
<!-- =================================================================================== -->
<!-- |    This document was autogenerated by xacro from chain1.xacro                   | -->
<!-- |    EDITING THIS FILE BY HAND IS NOT RECOMMENDED                                 | -->
<!-- =================================================================================== -->
<robot name="Chain" xmlns:xacro="http://www.ros.org/wiki/xacro">
  <link name="baselink"/>
  <link name="chainbase">
    <visual>
      <geometry>
        <box size="0.3 0.1 0.1"/>
      </geometry>
    </visual>
    <inertial>
      <mass value="1"/>
      <inertia ixx="0.00666666666667" ixy="0.0" ixz="0.0" iyy="0.0333333333333" iyz="0.0" izz="0.0333333333333"/>
    </inertial>
  </link>
  <link name="link1">
    <visual>
      <origin rpy="0 0 0" xyz="0.15 0.0 0"/>
      <geometry>
        <box size="0.3 0.1 0.1"/>
      </geometry>
      <material name="blue">
        <color rgba="0 0 0.8 1"/>
      </material>
    </visual>
    <inertial>
      <origin rpy="0 0 0" xyz="0.15 0.0 0"/>
      <mass value="1"/>
      <inertia ixx="0.00666666666667" ixy="0.0" ixz="0.0" iyy="0.0333333333333" iyz="0.0" izz="0.0333333333333"/>
    </inertial>
  </link>
  <link name="link2">
    <visual>
      <origin rpy="0 0 0" xyz="0.15 0.0 0"/>
      <geometry>
        <box size="0.3 0.1 0.1"/>
      </geometry>
      <material name="blue">
        <color rgba="0 0 0.8 1"/>
      </material>
    </visual>
    <inertial>
      <origin rpy="0 0 0" xyz="0.15 0.0 0"/>
      <mass value="1"/>
      <inertia ixx="0.00666666666667" ixy="0.0" ixz="0.0" iyy="0.0333333333333" iyz="0.0" izz="0.0333333333333"/>
    </inertial>
  </link>
  <!-- Joints -->
  <joint name="basetoroot" type="fixed">
    <parent link="baselink"/>
    <child link="chainbase"/>
    <origin rpy="0 0 0" xyz="0 0 0"/>
  </joint>
  <joint name="roottolink1" type="revolute">
    <parent link="chainbase"/>
    <child link="link1"/>
    <origin rpy="0 0 0" xyz="0.15 0.0 0"/>
    <axis xyz="0 0 1"/>
    <limit effort="30" lower="-5" upper="5" velocity="5.0"/>
  </joint>
  <joint name="link1tolink2" type="revolute">
    <parent link="link1"/>
    <child link="link2"/>
    <origin rpy="0 0 0" xyz="0.3 0.0 0"/>
    <axis xyz="0 0 1"/>
    <limit effort="30" lower="-5" upper="5" velocity="5.0"/>
  </joint>
</robot>

